Workbook

Sheet Staff
A1: Steve Arnott
A2: Humphrey Goodman
A3: Ted Hastings
A4: Neville Parker
A5: Christopher Foyle
A6: Robbie Lewis
A7: Richard Poole
A8: Kate Fleming
A9: Ellie Miller
A10: Jackson Brodie
A11: Cormoran Strike
A12: Marcella Backland
... A34: Adam Dalgliesh

Sheet SFIA Level
A1: Competence Level | B1: Numeric
A2: No Knowledge | B2: 0
A3: Awareness | B3: 1
A4: Working | B4: 2
A5: Practitioner | B5: 3
A6: Expert | B6: 4

Sheet Baseline
D1: Service Delivery | Q1: Service Operations | AG1: Service Resilience | AP1: Service Improvement | AU1: Future Roles
C2: Competency | D2: Service Desk | H2: Fulfilment | M2: Governance | P2: Service Delivery | Q2: Infrastructure | W2: Research Computing | AA2: Applications & Data | AG2: Resilience | AJ2: Governance | AL2: DevOps | AP2: Principal Engineers
D3: Assistant Systems Analyst | E3: Systems Analyst | F3: Senior Systems Analyst SD | G3: Service Desk Lead | H3: Senior Systems Analyst Ful | I3: Problem Analyst | J3: Fulfilment Lead | K3: Junior Systems Administrator | L3: Systems Administrator | M3: Senior Systems Administrator | N3: Service Fulfilment Lead | O3: Major incident manager | P3: Service Delivery Manager | Q3: Assistant Systems Administrator | R3: Systems Administrator | S3: Senior Systems Administrator | T3: Senior Network Adminsitrator | U3: Infrastructure Specialist | V3: Infrastructure Lead | W3: Assistant Systems Engineer | X3: Systems Engineer | Y3: Senior Systems Engineer | Z3: Research Computing Lead | AA3: Assistant Developer | AB3: Assistant Software Engineer | AC3: Software Engineer | AD3: Senior Software Engineer | AE3: Software Engineering Lead | AF3: Service Operations Manager | AG3: Service Resilience Analyst | AH3: Senior Systems Administrator (Vulnerabilities) | AI3: Junior IT Governance Administrator | AJ3: Systems Administrator (Governance) | AK3: Senior Systems Administrator (Governance) | AL3: Assistant Software Engineer DO | AM3: Software Engineer (DevOps) | AN3: Senior Software Engineer (DevOps) | AO3: Service Resilience Manager | AP3: Technical Relationship Lead | AQ3: Principal Engineer (Research Computing) | AR3: Principal Engineer (Infrastructure) | AS3: Principal Engineer (Linux) | AT3: Principal Engineer EdTech | AU3: Web Service Designer | AV3: Senior Web Service Designer | AW3: Database Administrator | AX3: Senior Database Administrator | AY3: Change and Release manager | AZ3: Solutions Architect
A4: CoSECore1 | B4: Asset Management | C4: Managing the full life cycle of assets from acquisition, operation, maintenance to disposal. | D4: Working | E4: Working | F4: Working | G4: Practitioner | H4: Practitioner | I4: Practitioner | J4: Practitioner | K4: Working | L4: Working | M4: Practitioner | N4: Practitioner | O4: Practitioner | P4: Practitioner | Q4: Working | R4: Working | S4: Working | T4: Working | U4: Working | V4: Working | W4: Working | X4: Working | Y4: Working | Z4: Working | AA4: Working | AB4: Working | AC4: Working | AD4: Working | AE4: Working | AF4: Practitioner | AG4: Working | AH4: Working | AI4: Working | AJ4: Practitioner | AK4: Expert | AL4: Working | AM4: Working | AN4: Working | AO4: Working | AP4: Practitioner | AQ4: Practitioner | AR4: Practitioner | AS4: Practitioner | AT4: Practitioner | AU4: Practitioner | AV4: Working | AW4: Working | AX4: Working | AY4: Expert | AZ4: Expert
A5: CoSECore2 | B5: Change Control | C5: Assessing risks associated with proposed changes and ensuring changes to products, services or systems are controlled and coordinated. | D5: Working | E5: Working | F5: Practitioner | G5: Expert | H5: Practitioner | I5: Practitioner | J5: Expert | K5: Working | L5: Working | M5: Practitioner | N5: Practitioner | O5: Practitioner | P5: Expert | Q5: Working | R5: Practitioner | S5: Practitioner | T5: Practitioner | U5: Practitioner | V5: Practitioner | W5: Working | X5: Working | Y5: Working | Z5: Practitioner | AA5: Working | AB5: Practitioner | AC5: Practitioner | AD5: Practitioner | AE5: Practitioner | AF5: Practitioner | AG5: Working | AH5: Practitioner | AI5: Awareness | AJ5: Working | AK5: Working | AL5: Working | AM5: Working | AN5: Working | AO5: Practitioner | AP5: Practitioner | AQ5: Practitioner | AR5: Practitioner | AS5: Practitioner | AT5: Practitioner | AU5: Practitioner | AV5: Practitioner | AW5: Practitioner | AX5: Practitioner
A6: CoSECore3 | B6: Customer Service Support | C6: Managing and operating customer service or service desk functions. | D6: Working | E6: Practitioner | F6: Practitioner | G6: Expert | H6: Practitioner | I6: Practitioner | J6: Expert | K6: Working | L6: Practitioner | M6: Practitioner | N6: Practitioner | O6: Practitioner | P6: Expert | Q6: Working | R6: Practitioner | S6: Practitioner | T6: Practitioner | U6: Practitioner | V6: Practitioner | W6: Working | X6: Practitioner | Y6: Practitioner | Z6: Practitioner | AA6: Working | AB6: Practitioner | AC6: Practitioner | AD6: Practitioner | AE6: Practitioner | AF6: Practitioner | AG6: Practitioner | AH6: Practitioner | AI6: Working | AJ6: Practitioner | AK6: Practitioner | AL6: Practitioner | AM6: Practitioner | AN6: Practitioner | AO6: Practitioner | AP6: Practitioner | AQ6: Practitioner | AR6: Practitioner | AS6: Practitioner | AT6: Practitioner | AU6: Working | AV6: Working | AW6: Working | AX6: Working | AY6: Working | AZ6: Working
A7: CoSECore5 | B7: Incident management | C7: Coordinating responses to incident reports, minimising negative impacts and restoring service as quickly as possible. | D7: Working | E7: Working | F7: Practitioner | G7: Expert | H7: Practitioner | I7: Practitioner | J7: Expert | K7: Working | L7: Practitioner | M7: Practitioner | N7: Practitioner | O7: Practitioner | P7: Practitioner | Q7: Working | R7: Working | S7: Working | T7: Working | U7: Working | V7: Working | W7: Working | X7: Working | Y7: Working | Z7: Working | AA7: Working | AB7: Working | AC7: Working | AD7: Practitioner | AE7: Practitioner | AF7: Practitioner | AG7: Working | AH7: Working | AI7: Working | AJ7: Practitioner | AK7: Practitioner | AL7: Working | AM7: Working | AN7: Working | AO7: Practitioner | AP7: Practitioner | AQ7: Practitioner | AR7: Practitioner | AS7: Practitioner | AT7: Practitioner | AU7: Practitioner | AV7: Practitioner | AW7: Practitioner | AX7: Practitioner
A8: CoSECore6 | B8: Information security | C8: Defining and operating a framework of security controls and security management strategies. | D8: Working | E8: Working | F8: Practitioner | G8: Practitioner | H8: Practitioner | I8: Practitioner | J8: Practitioner | K8: Working | L8: Working | M8: Practitioner | N8: Practitioner | O8: Practitioner | P8: Practitioner | Q8: Working | R8: Practitioner | S8: Practitioner | T8: Practitioner | U8: Practitioner | V8: Practitioner | W8: Working | X8: Practitioner | Y8: Practitioner | Z8: Practitioner | AA8: Working | AB8: Working | AC8: Practitioner | AD8: Practitioner | AE8: Practitioner | AF8: Practitioner | AG8: Practitioner | AH8: Practitioner | AI8: Working | AJ8: Working | AK8: Practitioner | AL8: Practitioner | AM8: Practitioner | AN8: Practitioner | AO8: Expert | AP8: Practitioner | AQ8: Practitioner | AR8: Practitioner | AS8: Practitioner | AT8: Practitioner | AU8: Practitioner | AV8: Practitioner | AW8: Practitioner | AX8: Practitioner | AY8: Practitioner | AZ8: Practitioner
A9: CoSECore7 | B9: Personal data protection | C9: Implementing and operating a framework of controls and management strategies to promote compliance with personal data legislation. | D9: Working | E9: Practitioner | F9: Practitioner | G9: Practitioner | H9: Practitioner | I9: Practitioner | J9: Practitioner | K9: Working | L9: Practitioner | M9: Practitioner | N9: Practitioner | O9: Practitioner | P9: Practitioner | Q9: Practitioner | R9: Practitioner | S9: Practitioner | T9: Practitioner | U9: Practitioner | V9: Practitioner | W9: Practitioner | X9: Practitioner | Y9: Practitioner | Z9: Practitioner | AA9: Working | AB9: Working | AC9: Practitioner | AD9: Practitioner | AE9: Practitioner | AF9: Practitioner | AG9: Practitioner | AH9: Practitioner | AI9: Working | AJ9: Practitioner | AK9: Practitioner | AL9: Practitioner | AM9: Practitioner | AN9: Practitioner | AO9: Expert | AP9: Practitioner | AQ9: Practitioner | AR9: Practitioner | AS9: Practitioner | AT9: Practitioner | AU9: Working | AV9: Working | AW9: Working | AX9: Working | AY9: Working | AZ9: Working
A10: CoSESvc07 | B10: Problem management | C10: Managing the life cycle of all problems that have occurred or could occur in delivering a service. | D10: Working | E10: Working | F10: Practitioner | G10: Expert | H10: Practitioner | I10: Expert | J10: Expert | K10: Working | L10: Working | M10: Working | N10: Working | O10: Practitioner | P10: Expert | Q10: Working | R10: Working | S10: Practitioner | T10: Practitioner | U10: Expert | V10: Expert | W10: Working | X10: Working | Y10: Practitioner | Z10: Working | AA10: Awareness | AB10: Working | AC10: Working | AD10: Working | AE10: Working | AF10: Working | AG10: Working | AH10: Practitioner | AI10: Working | AJ10: Working | AK10: Working | AL10: Working | AM10: Working | AN10: Working | AO10: Working | AP10: Working | AQ10: Working | AR10: Working | AS10: Working | AT10: Working | AU10: Working | AV10: Working | AW10: Working | AX10: Working | AY10: Working | AZ10: Working
A11: CoSESvc10 | B11: Service catalogue management | C11: Providing a source of consistent information about available services and products to customers and users. | D11: Working | E11: Working | F11: Practitioner | G11: Expert | H11: Practitioner | I11: Practitioner | J11: Expert | K11: Working | L11: Working | M11: Working | N11: Working | O11: Practitioner | P11: Expert | Q11: Working | R11: Working | S11: Practitioner | T11: Practitioner | U11: Expert | V11: Expert | W11: Working | X11: Working | Y11: Practitioner | Z11: Working | AA11: Awareness | AB11: Working | AC11: Working | AD11: Working | AE11: Working | AF11: Working | AG11: Working | AH11: Practitioner | AI11: Working | AJ11: Working | AK11: Working | AL11: Working | AM11: Working | AN11: Working | AO11: Working | AP11: Working | AQ11: Working | AR11: Working | AS11: Working | AT11: Working | AU11: Working | AV11: Working | AW11: Working | AX11: Working | AY11: Working | AZ11: Working
A12: CoSESvc11 | B12: Service level management | C12: Agreeing targets for service levels and assessing, monitoring, and managing the delivery of services against the targets. | D12: Working | E12: Working | F12: Practitioner | G12: Expert | H12: Working | I12: Working | J12: Expert | K12: Working | L12: Working | M12: Practitioner | N12: Practitioner | O12: Practitioner | P12: Expert | Q12: Working | R12: Working | S12: Practitioner | T12: Practitioner | U12: Expert | V12: Expert | W12: Working | X12: Working | Y12: Practitioner | Z12: Working | AA12: Awareness | AB12: Working | AC12: Working | AD12: Working | AE12: Working | AF12: Working | AG12: Working | AH12: Practitioner | AI12: No Knowledge | AJ12: Working | AK12: Working | AL12: Working | AM12: Working | AN12: Working | AO12: Working | AP12: Working | AQ12: Working | AR12: Working | AS12: Working | AT12: Working | AU12: Working | AV12: Working | AW12: Working | AX12: Working | AY12: Working | AZ12: Working
A13: CoSESvc01 | B13: Availability Management | C13: Ensuring that services deliver agreed levels of availability to meet the current and future needs of the business. | D13: Awareness | E13: Awareness | F13: Working | G13: Working | H13: Working | I13: Working | J13: Working | K13: Awareness | L13: Awareness | M13: Awareness | N13: Awareness | O13: Expert | P13: Expert | Q13: Working | R13: Working | S13: Practitioner | T13: Practitioner | U13: Expert | V13: Expert | W13: Working | X13: Working | Y13: Practitioner | Z13: Working | AA13: Awareness | AB13: Working | AC13: Working | AD13: Working | AE13: Working | AF13: Practitioner | AG13: Practitioner | AH13: Practitioner | AI13: Awareness | AJ13: Awareness | AK13: Awareness | AL13: Working | AM13: Working | AN13: Working | AO13: Expert | AP13: Practitioner | AQ13: Practitioner | AR13: Practitioner | AS13: Practitioner | AT13: Practitioner | AY13: Practitioner | AZ13: Practitioner
A14: CoSESvc02 | B14: Capacity management | C14: Ensuring that service components have the capacity and performance to meet current and planned business needs. | D14: No Knowledge | E14: No Knowledge | F14: No Knowledge | G14: No Knowledge | H14: No Knowledge | I14: No Knowledge | J14: No Knowledge | K14: Awareness | L14: No Knowledge | M14: No Knowledge | N14: No Knowledge | O14: Working | P14: Working | Q14: Working | R14: Working | S14: Practitioner | T14: Practitioner | U14: Expert | V14: Expert | W14: Working | X14: Working | Y14: Practitioner | Z14: No Knowledge | AA14: Awareness | AB14: Working | AC14: Working | AD14: Working | AE14: Working | AF14: Practitioner | AG14: No Knowledge | AH14: Practitioner | AI14: Awareness | AJ14: No Knowledge | AK14: No Knowledge | AL14: No Knowledge | AM14: No Knowledge | AN14: No Knowledge | AO14: No Knowledge | AP14: Practitioner | AQ14: Practitioner | AR14: Practitioner | AS14: Practitioner | AT14: Practitioner
A15: CoSESvc03 | B15: Configuration Management | C15: Planning, identifying, controlling, accounting for and auditing of configuration items (CIs) and their interrelationships. | D15: Awareness | E15: Awareness | F15: Awareness | G15: Awareness | H15: Awareness | I15: Awareness | J15: Awareness | K15: Awareness | L15: Awareness | M15: Working | N15: Working | O15: Working | P15: Working | Q15: Working | R15: Working | S15: Practitioner | T15: Practitioner | U15: Expert | V15: Expert | W15: Working | X15: Working | Y15: Practitioner | Z15: Working | AA15: Awareness | AB15: Working | AC15: Working | AD15: Working | AE15: Working | AF15: Practitioner | AG15: No Knowledge | AH15: Practitioner | AI15: Awareness | AJ15: No Knowledge | AK15: No Knowledge | AL15: Working | AM15: Working | AN15: Working | AO15: No Knowledge | AP15: Practitioner | AQ15: Practitioner | AR15: Practitioner | AS15: Practitioner | AT15: Practitioner
A16: CoSESvc04 | B16: Continuity Management | C16: Developing, implementing and testing a business continuity framework. | D16: Awareness | E16: Awareness | F16: Awareness | G16: Awareness | H16: Awareness | I16: Awareness | J16: Awareness | K16: Awareness | L16: Awareness | M16: Awareness | N16: Awareness | O16: Practitioner | P16: Practitioner | Q16: Working | R16: Working | S16: Practitioner | T16: Practitioner | U16: Expert | V16: Expert | W16: Working | X16: Working | Y16: Practitioner | Z16: Working | AA16: Awareness | AB16: Working | AC16: Working | AD16: Working | AE16: Working | AF16: Practitioner | AG16: Practitioner | AH16: Practitioner | AI16: Awareness | AJ16: Awareness | AK16: Awareness | AL16: Working | AM16: Working | AN16: Working | AO16: Practitioner | AP16: Practitioner | AQ16: Practitioner | AR16: Practitioner | AS16: Practitioner | AT16: Practitioner | AU16: Practitioner | AV16: Practitioner | AW16: Practitioner | AX16: Practitioner
A17: CoSECore4 | B17: Demand Management | C17: Analysing and proactively managing business demand for new services or modifications to existing service features or volumes. | D17: Awareness | E17: Awareness | F17: Awareness | G17: Awareness | H17: Awareness | I17: Awareness | J17: Awareness | K17: Awareness | L17: Working | M17: Working | N17: Working | O17: Working | P17: Expert | Q17: Working | R17: Practitioner | S17: Practitioner | T17: Practitioner | U17: Practitioner | V17: Practitioner | W17: Working | X17: Practitioner | Y17: Practitioner | Z17: Practitioner | AA17: Awareness | AB17: Working | AC17: Working | AD17: Practitioner | AE17: Practitioner | AF17: Practitioner | AG17: Practitioner | AH17: Practitioner | AI17: Awareness | AJ17: Working | AK17: Working | AL17: Practitioner | AM17: Practitioner | AN17: Practitioner | AO17: Practitioner | AP17: Practitioner | AQ17: Practitioner | AR17: Practitioner | AS17: Practitioner | AT17: Practitioner | AU17: Working | AV17: Working | AW17: Working | AX17: Working
A18: CoSESvc05 | B18: Knowledge management | C18: Managing vital knowledge to create value for the organisation. | D18: Working | E18: Working | F18: Working | G18: Working | H18: Working | I18: Working | J18: Working | K18: Working | L18: Working | M18: Working | N18: Working | O18: Working | P18: Practitioner | Q18: Working | R18: Working | S18: Practitioner | T18: Practitioner | U18: Expert | V18: Expert | W18: Working | X18: Working | Y18: Practitioner | Z18: Working | AA18: Awareness | AB18: Working | AC18: Working | AD18: Practitioner | AE18: Practitioner | AF18: Practitioner | AG18: Practitioner | AH18: Practitioner | AI18: Working | AJ18: Working | AK18: Working | AL18: Working | AM18: Working | AN18: Working | AO18: Practitioner | AP18: Practitioner | AQ18: Practitioner | AR18: Practitioner | AS18: Practitioner | AT18: Practitioner
A19: CoSESvc06 | B19: Methods and tools | C19: Ensuring methods and tools are adopted and used effectively throughout the organisation. | D19: Awareness | E19: Awareness | F19: Awareness | G19: Awareness | H19: Awareness | I19: Practitioner | J19: Awareness | K19: Awareness | L19: Working | M19: Working | N19: Practitioner | O19: Expert | P19: Expert | Q19: Working | R19: Working | S19: Practitioner | T19: Practitioner | U19: Expert | V19: Expert | W19: Working | X19: Working | Y19: Practitioner | Z19: Practitioner | AA19: Awareness | AB19: Working | AC19: Practitioner | AD19: Expert | AE19: Expert | AF19: Practitioner | AG19: Practitioner | AH19: Practitioner | AI19: Awareness | AJ19: Awareness | AK19: Awareness | AL19: Practitioner | AM19: Practitioner | AN19: Expert | AO19: Practitioner | AP19: Practitioner | AQ19: Practitioner | AR19: Practitioner | AS19: Practitioner | AT19: Practitioner
A20: CoSESvc08 | B20: Release and deployment | C20: Applying the processes, systems and functions required to make new and changed services and features available for use. | D20: No Knowledge | E20: No Knowledge | F20: No Knowledge | G20: Awareness | H20: Awareness | I20: Awareness | J20: Awareness | K20: No Knowledge | L20: No Knowledge | M20: No Knowledge | N20: No Knowledge | O20: No Knowledge | P20: Working | Q20: Working | R20: Working | S20: Practitioner | T20: Practitioner | U20: Expert | V20: Expert | W20: Working | X20: Working | Y20: Practitioner | Z20: Practitioner | AA20: Awareness | AB20: Working | AC20: Practitioner | AD20: Expert | AE20: Expert | AF20: Practitioner | AG20: Practitioner | AH20: Practitioner | AI20: N/A | AJ20: No Knowledge | AK20: No Knowledge | AL20: Practitioner | AM20: Practitioner | AN20: Expert | AO20: Expert | AP20: Practitioner | AQ20: Practitioner | AR20: Practitioner | AS20: Practitioner | AT20: Practitioner
A21: CoSESvc09 | B21: Service acceptance | C21: Managing the process to obtain formal confirmation that service acceptance criteria have been met. | D21: No Knowledge | E21: No Knowledge | F21: No Knowledge | G21: Practitioner | H21: Working | I21: Working | J21: Practitioner | K21: No Knowledge | L21: No Knowledge | M21: No Knowledge | N21: No Knowledge | O21: Practitioner | P21: Expert | Q21: Working | R21: Working | S21: Practitioner | T21: Practitioner | U21: Expert | V21: Expert | W21: Working | X21: Working | Y21: Practitioner | Z21: Practitioner | AA21: Awareness | AB21: Working | AC21: Practitioner | AD21: Expert | AE21: Expert | AF21: Practitioner | AG21: Practitioner | AH21: Practitioner | AI21: N/A | AJ21: No Knowledge | AK21: No Knowledge | AL21: Practitioner | AM21: Practitioner | AN21: Expert | AO21: Practitioner | AP21: Practitioner | AQ21: Practitioner | AR21: Practitioner | AS21: Practitioner | AT21: Practitioner
A22: CoSESvc12 | B22: Stakeholder relationship management | C22: Influencing stakeholder attitudes, decisions, and actions for mutual benefit. | D22: Awareness | E22: Working | F22: Practitioner | G22: Practitioner | H22: Practitioner | I22: Expert | J22: Practitioner | K22: Awareness | L22: Working | M22: Practitioner | N22: Practitioner | O22: Practitioner | P22: Expert | Q22: Working | R22: Working | S22: Practitioner | T22: Practitioner | U22: Expert | V22: Expert | W22: Working | X22: Working | Y22: Practitioner | Z22: Working | AA22: Awareness | AB22: Working | AC22: Working | AD22: Practitioner | AE22: Practitioner | AF22: Practitioner | AG22: Practitioner | AH22: Practitioner | AI22: Awareness | AJ22: Working | AK22: Working | AL22: Working | AM22: Working | AN22: Practitioner | AO22: Practitioner | AP22: Practitioner | AQ22: Practitioner | AR22: Practitioner | AS22: Practitioner | AT22: Practitioner | AY22: Practitioner | AZ22: Practitioner
A23: CoSESvc14 | B23: Storage management | C23: Planning, implementing and optimising the technologies and processes used for data storage. | D23: Awareness | E23: Working | F23: Working | G23: Working | H23: Working | I23: Working | J23: Working | K23: Awareness | L23: Working | M23: Working | N23: Working | O23: Working | P23: Working | Q23: Working | R23: Working | S23: Practitioner | T23: Practitioner | U23: Expert | V23: Expert | W23: Working | X23: Working | Y23: Practitioner | Z23: Awareness | AA23: Awareness | AB23: Awareness | AC23: Awareness | AD23: Awareness | AE23: Awareness | AF23: Practitioner | AG23: Awareness | AH23: Practitioner | AI23: Awareness | AJ23: Working | AK23: Working | AL23: Awareness | AM23: Awareness | AN23: Awareness | AO23: Awareness | AP23: Practitioner | AQ23: Practitioner | AR23: Practitioner | AS23: Practitioner | AT23: Practitioner
A24: CoSESec01 | B24: Digital Forensics | C24: Recovering and investigating material found in digital devices. | D24: No Knowledge | E24: No Knowledge | F24: No Knowledge | G24: No Knowledge | H24: No Knowledge | I24: No Knowledge | J24: No Knowledge | K24: No Knowledge | L24: No Knowledge | M24: No Knowledge | N24: No Knowledge | O24: No Knowledge | P24: No Knowledge | Q24: No Knowledge | R24: No Knowledge | S24: No Knowledge | T24: No Knowledge | U24: No Knowledge | V24: No Knowledge | W24: Working | X24: Working | Y24: Working | Z24: Awareness | AA24: Working | AB24: Working | AC24: Practitioner | AD24: Practitioner | AE24: Practitioner | AF24: Practitioner | AG24: Practitioner | AH24: No Knowledge | AI24: No Knowledge | AJ24: No Knowledge | AK24: No Knowledge | AL24: Working | AM24: Practitioner | AN24: Practitioner | AO24: Expert | AP24: Practitioner | AQ24: Practitioner | AR24: Practitioner | AS24: Practitioner | AT24: Practitioner | AU24: Expert | AV24: Expert | AW24: Expert | AX24: Expert
A25: CoSESec02 | B25: Penetration testing | C25: Testing the effectiveness of security controls by emulating the tools and techniques of likely attackers. | D25: No Knowledge | E25: No Knowledge | F25: No Knowledge | G25: No Knowledge | H25: No Knowledge | I25: No Knowledge | J25: No Knowledge | K25: No Knowledge | L25: No Knowledge | M25: No Knowledge | N25: No Knowledge | O25: No Knowledge | P25: Awareness | Q25: Awareness | R25: Awareness | S25: Working | T25: Working | U25: Practitioner | V25: Practitioner | W25: Awareness | X25: Awareness | Y25: Working | Z25: Working | AA25: Working | AB25: Working | AC25: Working | AD25: Practitioner | AE25: Practitioner | AF25: Practitioner | AG25: Practitioner | AH25: Working | AI25: No Knowledge | AJ25: No Knowledge | AK25: No Knowledge | AL25: Practitioner | AM25: Practitioner | AN25: Expert | AO25: Expert | AP25: Practitioner | AQ25: Practitioner | AR25: Practitioner | AS25: Practitioner | AT25: Practitioner | AU25: Expert | AV25: Expert | AW25: Expert | AX25: Expert
A26: CoSESec03 | B26: Security Operations | C26: Delivering management, technical and administrative services to implement security controls and security management strategies. | D26: Awareness | E26: Working | F26: Practitioner | G26: Practitioner | H26: Practitioner | I26: Practitioner | J26: Practitioner | K26: Awareness | L26: Working | M26: Practitioner | N26: Practitioner | O26: No Knowledge | P26: Practitioner | Q26: Awareness | R26: Working | S26: Practitioner | T26: Practitioner | U26: Practitioner | V26: Practitioner | W26: Working | X26: Working | Y26: Practitioner | Z26: Practitioner | AA26: Working | AB26: Working | AC26: Practitioner | AD26: Practitioner | AE26: Practitioner | AF26: Expert | AG26: Practitioner | AH26: Practitioner | AI26: Awareness | AJ26: Working | AK26: Practitioner | AL26: Practitioner | AM26: Practitioner | AN26: Expert | AO26: Expert | AP26: Expert | AQ26: Expert | AR26: Expert | AS26: Expert | AT26: Expert | AU26: Expert | AV26: Expert | AW26: Expert | AX26: Expert
A27: CoSESec04 | B27: Threat Intelligence | C27: Developing and sharing actionable insights on current and potential security threats to the success or integrity of an organisation. | D27: No Knowledge | E27: No Knowledge | F27: No Knowledge | G27: No Knowledge | H27: No Knowledge | I27: No Knowledge | J27: No Knowledge | K27: No Knowledge | L27: No Knowledge | M27: No Knowledge | N27: No Knowledge | O27: No Knowledge | P27: No Knowledge | Q27: No Knowledge | R27: No Knowledge | S27: Awareness | T27: Awareness | U27: Working | V27: Working | W27: Awareness | X27: Awareness | Y27: Working | Z27: Working | AA27: Awareness | AB27: Working | AC27: Working | AD27: Practitioner | AE27: Practitioner | AF27: Expert | AG27: Practitioner | AH27: Awareness | AI27: No Knowledge | AJ27: No Knowledge | AK27: No Knowledge | AL27: Practitioner | AM27: Practitioner | AN27: Expert | AO27: Expert | AP27: Expert | AQ27: Expert | AR27: Expert | AS27: Expert | AT27: Expert | AU27: Expert | AV27: Expert | AW27: Expert | AX27: Expert
A28: CoSESec05 | B28: Vulnerability assessment | C28: Identifying and classifying security vulnerabilities in networks, systems and applications and mitigating or eliminating their impact. | D28: Awareness | E28: Working | F28: Working | G28: Working | H28: Working | I28: Working | J28: Working | K28: Awareness | L28: Working | M28: Working | N28: Working | O28: No Knowledge | P28: Working | Q28: Awareness | R28: Working | S28: Practitioner | T28: Practitioner | U28: Practitioner | V28: Practitioner | W28: Working | X28: Working | Y28: Working | Z28: Practitioner | AA28: Working | AB28: Working | AC28: Working | AD28: Practitioner | AE28: Practitioner | AF28: Expert | AG28: Practitioner | AH28: Practitioner | AI28: Awareness | AJ28: Working | AK28: Working | AL28: Practitioner | AM28: Practitioner | AN28: Expert | AO28: Expert | AP28: Expert | AQ28: Expert | AR28: Expert | AS28: Expert | AT28: Expert | AU28: No Knowledge | AV28: No Knowledge | AW28: No Knowledge | AX28: No Knowledge
A29: CoSESec06 | B29: Vulnerability Research | C29: Conducting applied research to discover, evaluate and mitigate new or unknown security vulnerabilities and weaknesses. | D29: No Knowledge | E29: No Knowledge | F29: No Knowledge | G29: No Knowledge | H29: No Knowledge | I29: No Knowledge | J29: No Knowledge | K29: No Knowledge | L29: No Knowledge | M29: No Knowledge | N29: No Knowledge | O29: No Knowledge | P29: No Knowledge | Q29: No Knowledge | R29: No Knowledge | S29: Awareness | T29: Awareness | U29: Working | V29: Working | W29: Awareness | X29: Awareness | Y29: Awareness | Z29: Awareness | AA29: No Knowledge | AB29: No Knowledge | AC29: No Knowledge | AD29: No Knowledge | AE29: No Knowledge | AF29: No Knowledge | AG29: Practitioner | AH29: Awareness | AI29: No Knowledge | AJ29: No Knowledge | AK29: No Knowledge | AL29: No Knowledge | AM29: No Knowledge | AN29: No Knowledge | AO29: Expert | AP29: No Knowledge | AQ29: No Knowledge | AR29: No Knowledge | AS29: No Knowledge | AT29: No Knowledge | AU29: Awareness | AV29: Awareness | AW29: Awareness | AX29: Awareness | AY29: Awareness | AZ29: Awareness
A30: CoseMgt01 | B30: Competency assessment | C30: Assessing knowledge, skills, competency and behaviours by any means, whether formal or informal, against frameworks such as SFIA. | D30: Awareness | E30: Awareness | F30: Awareness | G30: Working | H30: Awareness | I30: Awareness | J30: Working | K30: Awareness | L30: Awareness | M30: Awareness | N30: Working | O30: Awareness | P30: Practitioner | Q30: Awareness | R30: Awareness | S30: Awareness | T30: Awareness | U30: Awareness | V30: Working | W30: Awareness | X30: Awareness | Y30: Awareness | Z30: Working | AA30: Awareness | AB30: Awareness | AC30: Awareness | AD30: Awareness | AE30: Awareness | AF30: Practitioner | AG30: Awareness | AH30: Awareness | AI30: Awareness | AJ30: Awareness | AK30: Working | AL30: Awareness | AM30: Awareness | AN30: Awareness | AO30: Practitioner | AP30: Practitioner | AQ30: Working | AR30: Working | AS30: Working | AT30: Working | AU30: Awareness | AV30: Awareness | AW30: Awareness | AX30: Awareness | AY30: Awareness | AZ30: Awareness
A31: CoseMgt03 | B31: Financial management | C31: Supporting the effective use and control of financial resources. | D31: Awareness | E31: Awareness | F31: Awareness | G31: Working | H31: Awareness | I31: Awareness | J31: Working | K31: Working | L31: Working | M31: Working | N31: Working | O31: Awareness | P31: Awareness | Q31: Awareness | R31: Awareness | S31: Awareness | T31: Awareness | U31: Working | V31: Working | W31: No Knowledge | X31: No Knowledge | Y31: No Knowledge | Z31: Working | AA31: No Knowledge | AB31: No Knowledge | AC31: No Knowledge | AD31: No Knowledge | AE31: No Knowledge | AF31: Awareness | AG31: Awareness | AH31: Awareness | AI31: Awareness | AJ31: Working | AK31: Working | AL31: No Knowledge | AM31: No Knowledge | AN31: No Knowledge | AO31: Awareness | AP31: Awareness | AQ31: Practitioner | AR31: Practitioner | AS31: Practitioner | AT31: Practitioner | AU31: No Knowledge | AV31: No Knowledge | AW31: No Knowledge | AX31: No Knowledge | AY31: N/A | AZ31: N/A
A32: CoseMgt04 | B32: Organisation design and implementation | C32: Planning, designing and implementing an integrated organisation structure and culture. | D32: No Knowledge | E32: No Knowledge | F32: No Knowledge | G32: No Knowledge | H32: No Knowledge | I32: No Knowledge | J32: No Knowledge | K32: No Knowledge | L32: No Knowledge | M32: No Knowledge | N32: No Knowledge | O32: No Knowledge | P32: Awareness | Q32: No Knowledge | R32: No Knowledge | S32: No Knowledge | T32: No Knowledge | U32: No Knowledge | V32: No Knowledge | W32: No Knowledge | X32: No Knowledge | Y32: No Knowledge | Z32: No Knowledge | AA32: No Knowledge | AB32: No Knowledge | AC32: No Knowledge | AD32: No Knowledge | AE32: No Knowledge | AF32: Awareness | AG32: No Knowledge | AH32: No Knowledge | AI32: No Knowledge | AJ32: No Knowledge | AK32: No Knowledge | AL32: No Knowledge | AM32: No Knowledge | AN32: No Knowledge | AO32: Awareness | AP32: Awareness | AQ32: No Knowledge | AR32: No Knowledge | AS32: No Knowledge | AT32: No Knowledge | AU32: No Knowledge | AV32: No Knowledge | AW32: No Knowledge | AX32: No Knowledge | AY32: N/A | AZ32: N/A
A33: CoseMgt05 | B33: Organisational capability development | C33: Providing leadership, advice and implementation support to assess organisational capabilities and to identify, prioritise and implement improvements. | D33: No Knowledge | E33: No Knowledge | F33: No Knowledge | G33: No Knowledge | H33: No Knowledge | I33: No Knowledge | J33: No Knowledge | K33: No Knowledge | L33: No Knowledge | M33: No Knowledge | N33: No Knowledge | O33: No Knowledge | P33: Awareness | Q33: No Knowledge | R33: No Knowledge | S33: No Knowledge | T33: No Knowledge | U33: No Knowledge | V33: No Knowledge | W33: No Knowledge | X33: No Knowledge | Y33: No Knowledge | Z33: No Knowledge | AA33: No Knowledge | AB33: No Knowledge | AC33: No Knowledge | AD33: No Knowledge | AE33: No Knowledge | AF33: Awareness | AG33: No Knowledge | AH33: No Knowledge | AI33: No Knowledge | AJ33: No Knowledge | AK33: No Knowledge | AL33: No Knowledge | AM33: No Knowledge | AN33: No Knowledge | AO33: Awareness | AP33: Awareness | AQ33: No Knowledge | AR33: No Knowledge | AS33: No Knowledge | AT33: No Knowledge | AU33: No Knowledge | AV33: No Knowledge | AW33: No Knowledge | AX33: No Knowledge | AY33: N/A | AZ33: N/A
A34: CoseMgt06 | B34: Organisational change management | C34: Planning, designing and implementing activities to transition the organisation and people to the required future state. | D34: No Knowledge | E34: No Knowledge | F34: No Knowledge | G34: Awareness | H34: No Knowledge | I34: No Knowledge | J34: Awareness | K34: No Knowledge | L34: No Knowledge | M34: No Knowledge | N34: No Knowledge | O34: No Knowledge | P34: Working | Q34: No Knowledge | R34: No Knowledge | S34: No Knowledge | T34: No Knowledge | U34: Awareness | V34: Awareness | W34: No Knowledge | X34: No Knowledge | Y34: No Knowledge | Z34: Awareness | AA34: No Knowledge | AB34: No Knowledge | AC34: No Knowledge | AD34: No Knowledge | AE34: No Knowledge | AF34: Working | AG34: No Knowledge | AH34: No Knowledge | AI34: N/A | AJ34: No Knowledge | AK34: No Knowledge | AL34: No Knowledge | AM34: No Knowledge | AN34: No Knowledge | AO34: No Knowledge | AP34: Awareness | AQ34: No Knowledge | AR34: No Knowledge | AS34: No Knowledge | AT34: No Knowledge | AU34: No Knowledge | AV34: No Knowledge | AW34: No Knowledge | AX34: No Knowledge | AY34: N/A | AZ34: N/A
A35: CoseMgt07 | B35: Performance Management | C35: Improving organisational performance by developing the performance of individuals and workgroups to meet agreed objectives with measurable results. | D35: No Knowledge | E35: No Knowledge | F35: No Knowledge | G35: Working | H35: No Knowledge | I35: No Knowledge | J35: Working | K35: No Knowledge | L35: No Knowledge | M35: No Knowledge | N35: Working | O35: No Knowledge | P35: Working | Q35: No Knowledge | R35: No Knowledge | S35: No Knowledge | T35: No Knowledge | U35: Awareness | V35: Working | W35: No Knowledge | X35: No Knowledge | Y35: No Knowledge | Z35: Working | AA35: No Knowledge | AB35: Awareness | AC35: Awareness | AD35: Awareness | AE35: Awareness | AF35: Working | AG35: No Knowledge | AH35: No Knowledge | AI35: N/A | AJ35: No Knowledge | AK35: Working | AL35: No Knowledge | AM35: No Knowledge | AN35: No Knowledge | AO35: Working | AP35: No Knowledge | AQ35: No Knowledge | AR35: No Knowledge | AS35: No Knowledge | AT35: No Knowledge | AU35: Awareness | AV35: Awareness | AW35: Awareness | AX35: Awareness | AY35: Awareness | AZ35: Awareness
A36: CoseMgt08 | B36: Professional Development | C36: Facilitating the professional development of individuals in line with their career goals and organisational requirements. | D36: Awareness | E36: Awareness | F36: Awareness | G36: Working | H36: Awareness | I36: Awareness | J36: Working | K36: No Knowledge | L36: No Knowledge | M36: No Knowledge | N36: Working | O36: No Knowledge | P36: Practitioner | Q36: Awareness | R36: Awareness | S36: Awareness | T36: Awareness | U36: Awareness | V36: Working | W36: Awareness | X36: Awareness | Y36: Awareness | Z36: Working | AA36: Working | AB36: Working | AC36: Working | AD36: Working | AE36: Working | AF36: Practitioner | AG36: Awareness | AH36: Awareness | AI36: Awareness | AJ36: Awareness | AK36: Awareness | AL36: Awareness | AM36: Awareness | AN36: Awareness | AO36: Practitioner | AP36: Awareness | AQ36: Awareness | AR36: Awareness | AS36: Awareness | AT36: Awareness | AU36: N/A | AV36: N/A | AW36: N/A | AX36: N/A | AY36: N/A | AZ36: N/A
A37: CoseMgt09 | B37: Strategic Planning | C37: Creating and maintaining a strategy to align organisational actions, plans and resources with business objectives. | D37: No Knowledge | E37: No Knowledge | F37: No Knowledge | G37: Awareness | H37: No Knowledge | I37: No Knowledge | J37: Awareness | K37: No Knowledge | L37: No Knowledge | M37: No Knowledge | N37: No Knowledge | O37: No Knowledge | P37: Working | Q37: No Knowledge | R37: No Knowledge | S37: No Knowledge | T37: No Knowledge | U37: Awareness | V37: Awareness | W37: No Knowledge | X37: No Knowledge | Y37: No Knowledge | Z37: Awareness | AA37: No Knowledge | AB37: No Knowledge | AC37: No Knowledge | AD37: No Knowledge | AE37: No Knowledge | AF37: Working | AG37: No Knowledge | AH37: No Knowledge | AI37: N/A | AJ37: No Knowledge | AK37: No Knowledge | AL37: No Knowledge | AM37: No Knowledge | AN37: No Knowledge | AO37: Working | AP37: Working | AQ37: Working | AR37: Working | AS37: Working | AT37: Working | AU37: N/A | AV37: N/A | AW37: N/A | AX37: N/A | AY37: N/A | AZ37: N/A
A38: CoseMgt09 | B38: Workforce Planning | C38: Estimating the demand for people and skills and planning the supply needed to meet that demand. | D38: No Knowledge | E38: No Knowledge | F38: No Knowledge | G38: Working | H38: No Knowledge | I38: No Knowledge | J38: Working | K38: No Knowledge | L38: No Knowledge | M38: No Knowledge | N38: Working | O38: No Knowledge | P38: Practitioner | Q38: No Knowledge | R38: No Knowledge | S38: No Knowledge | T38: No Knowledge | U38: Awareness | V38: Working | W38: No Knowledge | X38: No Knowledge | Y38: No Knowledge | Z38: Working | AA38: No Knowledge | AB38: No Knowledge | AC38: No Knowledge | AD38: No Knowledge | AE38: No Knowledge | AF38: Practitioner | AG38: No Knowledge | AH38: No Knowledge | AI38: N/A | AJ38: No Knowledge | AK38: Working | AL38: No Knowledge | AM38: No Knowledge | AN38: No Knowledge | AO38: Practitioner | AP38: Working | AQ38: Working | AR38: Working | AS38: Working | AT38: Working
A39: CoSEGov01 | B39: Audit | C39: Delivering independent, risk-based assessments of the effectiveness of processes, the controls, and the compliance environment of an organisation. | D39: Awareness | E39: Awareness | F39: Working | G39: Working | H39: Working | I39: Working | J39: Working | K39: Awareness | L39: Working | M39: Working | N39: Practitioner | O39: No Knowledge | P39: Working | Q39: Working | R39: Working | S39: Working | T39: Working | U39: Working | V39: Working | W39: Working | X39: Working | Y39: Working | Z39: Practitioner | AA39: Awareness | AB39: Working | AC39: Working | AD39: Practitioner | AE39: Practitioner | AF39: Practitioner | AG39: Practitioner | AH39: Working | AI39: Awareness | AJ39: Working | AK39: Working | AL39: Working | AM39: Working | AN39: Practitioner | AO39: Expert | AP39: Practitioner | AQ39: Practitioner | AR39: Practitioner | AS39: Practitioner | AT39: Practitioner | AY39: Practitioner | AZ39: Practitioner
A40: CoSEGov02 | B40: Contract management | C40: Managing and controlling the operation of formal contracts for the supply of products and services. | D40: No Knowledge | E40: No Knowledge | F40: No Knowledge | G40: No Knowledge | H40: No Knowledge | I40: No Knowledge | J40: No Knowledge | K40: Awareness | L40: Working | M40: Working | N40: Expert | O40: No Knowledge | P40: Working | Q40: Working | R40: Working | S40: Working | T40: Working | U40: Working | V40: Working | W40: Awareness | X40: Awareness | Y40: Awareness | Z40: Practitioner | AA40: Awareness | AB40: Awareness | AC40: Awareness | AD40: Practitioner | AE40: Practitioner | AF40: Practitioner | AG40: Practitioner | AH40: Working | AI40: Working | AJ40: Working | AK40: Practitioner | AL40: Working | AM40: No Knowledge | AN40: Practitioner | AO40: Practitioner | AP40: Practitioner | AQ40: Practitioner | AR40: Practitioner | AS40: Practitioner | AT40: Practitioner | AY40: Practitioner | AZ40: Practitioner
...

Sheet Master
A1: Name | B1: New Role | C1: Competency | D1: Desired Description | E1: Comp Area | F1: Desired Level | G1: ActuaL | H1: Knowledge Gap | I1: Actual Copied (VLOOKUP)
A2: John Watson | B2: Senior Systems Administrator | C2: =VLOOKUP([1]Competence!$B12,[1]Competence!$B$12:$B$100,1,FALSE) -> Asset Management | D2: {=_xlfn.XLOOKUP(B2,[1]Baseline!$D$3:$AZ$3,_xlfn.XLOOKUP(C2,[1]Baseline!$B$4:$B$91,[1]Baseline!$D$4:$AZ$91))} -> Practitioner | E2: Business | F2: =VLOOKUP($D2,'[1]SFIA Level'!$A$2:$B$6,2,FALSE) -> 3 | G2: 3 | H2: =I2-F2 -> 0 | I2: 3
A3: John Watson | B3: Senior Systems Administrator | C3: =VLOOKUP([1]Competence!$B13,[1]Competence!$B$12:$B$100,1,FALSE) -> Change Control | D3: {=_xlfn.XLOOKUP(B3,[1]Baseline!$D$3:$AZ$3,_xlfn.XLOOKUP(C3,[1]Baseline!$B$4:$B$91,[1]Baseline!$D$4:$AZ$91))} -> Practitioner | E3: Business | F3: =VLOOKUP($D3,'[1]SFIA Level'!$A$2:$B$6,2,FALSE) -> 3 | G3: 3 | H3: =I3-F3 -> 0 | I3: 3
A4: John Watson | B4: Senior Systems Administrator | C4: =VLOOKUP([1]Competence!$B14,[1]Competence!$B$12:$B$100,1,FALSE) -> Customer Service Support | D4: {=_xlfn.XLOOKUP(B4,[1]Baseline!$D$3:$AZ$3,_xlfn.XLOOKUP(C4,[1]Baseline!$B$4:$B$91,[1]Baseline!$D$4:$AZ$91))} -> Practitioner | E4: Business | F4: =VLOOKUP($D4,'[1]SFIA Level'!$A$2:$B$6,2,FALSE) -> 3 | G4: 3 | H4: =I4-F4 -> 0 | I4: 3
A5: John Watson | B5: Senior Systems Administrator | C5: =VLOOKUP([1]Competence!$B15,[1]Competence!$B$12:$B$100,1,FALSE) -> Incident management | D5: {=_xlfn.XLOOKUP(B5,[1]Baseline!$D$3:$AZ$3,_xlfn.XLOOKUP(C5,[1]Baseline!$B$4:$B$91,[1]Baseline!$D$4:$AZ$91))} -> Practitioner | E5: Business | F5: =VLOOKUP($D5,'[1]SFIA Level'!$A$2:$B$6,2,FALSE) -> 3 | G5: 3 | H5: =I5-F5 -> 0 | I5: 3
A6: John Watson | B6: Senior Systems Administrator | C6: =VLOOKUP([1]Competence!$B16,[1]Competence!$B$12:$B$100,1,FALSE) -> Information security | D6: {=_xlfn.XLOOKUP(B6,[1]Baseline!$D$3:$AZ$3,_xlfn.XLOOKUP(C6,[1]Baseline!$B$4:$B$91,[1]Baseline!$D$4:$AZ$91))} -> Practitioner | E6: Service | F6: =VLOOKUP($D6,'[1]SFIA Level'!$A$2:$B$6,2,FALSE) -> 3 | G6: 2 | H6: =I6-F6 -> -1 | I6: 2
A7: John Watson | B7: Senior Systems Administrator | C7: =VLOOKUP([1]Competence!$B17,[1]Competence!$B$12:$B$100,1,FALSE) -> Personal data protection | D7: {=_xlfn.XLOOKUP(B7,[1]Baseline!$D$3:$AZ$3,_xlfn.XLOOKUP(C7,[1]Baseline!$B$4:$B$91,[1]Baseline!$D$4:$AZ$91))} -> Practitioner | E7: Governance | F7: =VLOOKUP($D7,'[1]SFIA Level'!$A$2:$B$6,2,FALSE) -> 3 | G7: 3 | H7: =I7-F7 -> 0 | I7: 3
A8: John Watson | B8: Senior Systems Administrator | C8: =VLOOKUP([1]Competence!$B18,[1]Competence!$B$12:$B$100,1,FALSE) -> Problem management | D8: {=_xlfn.XLOOKUP(B8,[1]Baseline!$D$3:$AZ$3,_xlfn.XLOOKUP(C8,[1]Baseline!$B$4:$B$91,[1]Baseline!$D$4:$AZ$91))} -> Working | E8: Governance | F8: =VLOOKUP($D8,'[1]SFIA Level'!$A$2:$B$6,2,FALSE) -> 2 | G8: 3 | H8: =I8-F8 -> 1 | I8: 3
A9: John Watson | B9: Senior Systems Administrator | C9: =VLOOKUP([1]Competence!$B19,[1]Competence!$B$12:$B$100,1,FALSE) -> Service catalogue management | D9: {=_xlfn.XLOOKUP(B9,[1]Baseline!$D$3:$AZ$3,_xlfn.XLOOKUP(C9,[1]Baseline!$B$4:$B$91,[1]Baseline!$D$4:$AZ$91))} -> Working | E9: Governance | F9: =VLOOKUP($D9,'[1]SFIA Level'!$A$2:$B$6,2,FALSE) -> 2 | G9: 2 | H9: =I9-F9 -> 0 | I9: 2
A10: John Watson | B10: Senior Systems Administrator | C10: =VLOOKUP([1]Competence!$B20,[1]Competence!$B$12:$B$100,1,FALSE) -> Service level management | D10: {=_xlfn.XLOOKUP(B10,[1]Baseline!$D$3:$AZ$3,_xlfn.XLOOKUP(C10,[1]Baseline!$B$4:$B$91,[1]Baseline!$D$4:$AZ$91))} -> Practitioner | E10: Technical | F10: =VLOOKUP($D10,'[1]SFIA Level'!$A$2:$B$6,2,FALSE) -> 3 | G10: 2 | H10: =I10-F10 -> -1 | I10: 2
A11: John Watson | B11: Senior Systems Administrator | C11: =VLOOKUP([1]Competence!$B21,[1]Competence!$B$12:$B$100,1,FALSE) -> Availability Management | D11: {=_xlfn.XLOOKUP(B11,[1]Baseline!$D$3:$AZ$3,_xlfn.XLOOKUP(C11,[1]Baseline!$B$4:$B$91,[1]Baseline!$D$4:$AZ$91))} -> Awareness | E11: Technical | F11: =VLOOKUP($D11,'[1]SFIA Level'!$A$2:$B$6,2,FALSE) -> 1 | G11: 3 | H11: =I11-F11 -> 2 | I11: 3
A12: John Watson | B12: Senior Systems Administrator | C12: =VLOOKUP([1]Competence!$B22,[1]Competence!$B$12:$B$100,1,FALSE) -> Capacity management | D12: {=_xlfn.XLOOKUP(B12,[1]Baseline!$D$3:$AZ$3,_xlfn.XLOOKUP(C12,[1]Baseline!$B$4:$B$91,[1]Baseline!$D$4:$AZ$91))} -> No Knowledge | E12: Business | F12: =VLOOKUP($D12,'[1]SFIA Level'!$A$2:$B$6,2,FALSE) -> 0 | G12: 3 | H12: =I12-F12 -> 3 | I12: 3
A13: John Watson | B13: Senior Systems Administrator | C13: =VLOOKUP([1]Competence!$B23,[1]Competence!$B$12:$B$100,1,FALSE) -> Configuration Management | D13: {=_xlfn.XLOOKUP(B13,[1]Baseline!$D$3:$AZ$3,_xlfn.XLOOKUP(C13,[1]Baseline!$B$4:$B$91,[1]Baseline!$D$4:$AZ$91))} -> Working | E13: Business | F13: =VLOOKUP($D13,'[1]SFIA Level'!$A$2:$B$6,2,FALSE) -> 2 | G13: 3 | H13: =I13-F13 -> 1 | I13: 3
... A89: John Watson | B89: Senior Systems Administrator | C89: =VLOOKUP([1]Competence!$B99,[1]Competence!$B$12:$B$100,1,FALSE) -> Quality assurance | D89: {=_xlfn.XLOOKUP(B89,[1]Baseline!$D$3:$AZ$3,_xlfn.XLOOKUP(C89,[1]Baseline!$B$4:$B$91,[1]Baseline!$D$4:$AZ$91))} -> Working | E89: Technical | F89: =VLOOKUP($D89,'[1]SFIA Level'!$A$2:$B$6,2,FALSE) -> 2 | G89: 0 | H89: =I89-F89 -> -2 | I89: 0
A90: Jane Marple | B90: Systems Analyst | C90: =VLOOKUP([1]Competence!$B12,[1]Competence!$B$12:$B$100,1,FALSE) -> Asset Management | D90: {=_xlfn.XLOOKUP(B90,[1]Baseline!$D$3:$AZ$3,_xlfn.XLOOKUP(C90,[1]Baseline!$B$4:$B$91,[1]Baseline!$D$4:$AZ$91))} -> Working | E90: Core | F90: =VLOOKUP($D90,'[1]SFIA Level'!$A$2:$B$6,2,FALSE) -> 2 | G90: 2 | H90: =I90-F90 -> 0 | I90: 2
A91: Jane Marple | B91: Systems Analyst | C91: =VLOOKUP([1]Competence!$B13,[1]Competence!$B$12:$B$100,1,FALSE) -> Change Control | D91: {=_xlfn.XLOOKUP(B91,[1]Baseline!$D$3:$AZ$3,_xlfn.XLOOKUP(C91,[1]Baseline!$B$4:$B$91,[1]Baseline!$D$4:$AZ$91))} -> Working | E91: Core | F91: =VLOOKUP($D91,'[1]SFIA Level'!$A$2:$B$6,2,FALSE) -> 2 | G91: 1 | H91: =I91-F91 -> -1 | I91: 1
A92: Jane Marple | B92: Systems Analyst | C92: =VLOOKUP([1]Competence!$B14,[1]Competence!$B$12:$B$100,1,FALSE) -> Customer Service Support | D92: {=_xlfn.XLOOKUP(B92,[1]Baseline!$D$3:$AZ$3,_xlfn.XLOOKUP(C92,[1]Baseline!$B$4:$B$91,[1]Baseline!$D$4:$AZ$91))} -> Practitioner | E92: Core | F92: =VLOOKUP($D92,'[1]SFIA Level'!$A$2:$B$6,2,FALSE) -> 3 | G92: 3 | H92: =I92-F92 -> 0 | I92: 3
A93: Jane Marple | B93: Systems Analyst | C93: =VLOOKUP([1]Competence!$B15,[1]Competence!$B$12:$B$100,1,FALSE) -> Incident management | D93: {=_xlfn.XLOOKUP(B93,[1]Baseline!$D$3:$AZ$3,_xlfn.XLOOKUP(C93,[1]Baseline!$B$4:$B$91,[1]Baseline!$D$4:$AZ$91))} -> Working | E93: Core | F93: =VLOOKUP($D93,'[1]SFIA Level'!$A$2:$B$6,2,FALSE) -> 2 | G93: 3 | H93: =I93-F93 -> 1 | I93: 3
A94: Jane Marple | B94: Systems Analyst | C94: =VLOOKUP([1]Competence!$B16,[1]Competence!$B$12:$B$100,1,FALSE) -> Information security | D94: {=_xlfn.XLOOKUP(B94,[1]Baseline!$D$3:$AZ$3,_xlfn.XLOOKUP(C94,[1]Baseline!$B$4:$B$91,[1]Baseline!$D$4:$AZ$91))} -> Working | E94: Core | F94: =VLOOKUP($D94,'[1]SFIA Level'!$A$2:$B$6,2,FALSE) -> 2 | G94: 1 | H94: =I94-F94 -> -1 | I94: 1
A95: Jane Marple | B95: Systems Analyst | C95: =VLOOKUP([1]Competence!$B17,[1]Competence!$B$12:$B$100,1,FALSE) -> Personal data protection | D95: {=_xlfn.XLOOKUP(B95,[1]Baseline!$D$3:$AZ$3,_xlfn.XLOOKUP(C95,[1]Baseline!$B$4:$B$91,[1]Baseline!$D$4:$AZ$91))} -> Practitioner | E95: Service | F95: =VLOOKUP($D95,'[1]SFIA Level'!$A$2:$B$6,2,FALSE) -> 3 | G95: 2 | H95: =I95-F95 -> -1 | I95: 2
A96: Jane Marple | B96: Systems Analyst | C96: =VLOOKUP([1]Competence!$B18,[1]Competence!$B$12:$B$100,1,FALSE) -> Problem management | D96: {=_xlfn.XLOOKUP(B96,[1]Baseline!$D$3:$AZ$3,_xlfn.XLOOKUP(C96,[1]Baseline!$B$4:$B$91,[1]Baseline!$D$4:$AZ$91))} -> Working | E96: Service | F96: =VLOOKUP($D96,'[1]SFIA Level'!$A$2:$B$6,2,FALSE) -> 2 | G96: 1 | H96: =I96-F96 -> -1 | I96: 1
A97: Jane Marple | B97: Systems Analyst | C97: =VLOOKUP([1]Competence!$B19,[1]Competence!$B$12:$B$100,1,FALSE) -> Service catalogue management | D97: {=_xlfn.XLOOKUP(B97,[1]Baseline!$D$3:$AZ$3,_xlfn.XLOOKUP(C97,[1]Baseline!$B$4:$B$91,[1]Baseline!$D$4:$AZ$91))} -> Working | E97: Service | F97: =VLOOKUP($D97,'[1]SFIA Level'!$A$2:$B$6,2,FALSE) -> 2 | G97: 3 | H97: =I97-F97 -> 1 | I97: 3
A98: Jane Marple | B98: Systems Analyst | C98: =VLOOKUP([1]Competence!$B20,[1]Competence!$B$12:$B$100,1,FALSE) -> Service level management | D98: {=_xlfn.XLOOKUP(B98,[1]Baseline!$D$3:$AZ$3,_xlfn.XLOOKUP(C98,[1]Baseline!$B$4:$B$91,[1]Baseline!$D$4:$AZ$91))} -> Working | E98: Security | F98: =VLOOKUP($D98,'[1]SFIA Level'!$A$2:$B$6,2,FALSE) -> 2 | G98: 1 | H98: =I98-F98 -> -1 | I98: 1
A99: Jane Marple | B99: Systems Analyst | C99: =VLOOKUP([1]Competence!$B21,[1]Competence!$B$12:$B$100,1,FALSE) -> Availability Management | D99: {=_xlfn.XLOOKUP(B99,[1]Baseline!$D$3:$AZ$3,_xlfn.XLOOKUP(C99,[1]Baseline!$B$4:$B$91,[1]Baseline!$D$4:$AZ$91))} -> Awareness | E99: Security | F99: =VLOOKUP($D99,'[1]SFIA Level'!$A$2:$B$6,2,FALSE) -> 1 | G99: 1 | H99: =I99-F99 -> 0 | I99: 1
A100: Jane Marple | B100: Systems Analyst | C100: =VLOOKUP([1]Competence!$B22,[1]Competence!$B$12:$B$100,1,FALSE) -> Capacity management | D100: {=_xlfn.XLOOKUP(B100,[1]Baseline!$D$3:$AZ$3,_xlfn.XLOOKUP(C100,[1]Baseline!$B$4:$B$91,[1]Baseline!$D$4:$AZ$91))} -> No Knowledge | E100: Management | F100: =VLOOKUP($D100,'[1]SFIA Level'!$A$2:$B$6,2,FALSE) -> 0 | G100: 2 | H100: =I100-F100 -> 2 | I100: 2
A101: Jane Marple | B101: Systems Analyst | C101: =VLOOKUP([1]Competence!$B23,[1]Competence!$B$12:$B$100,1,FALSE) -> Configuration Management | D101: {=_xlfn.XLOOKUP(B101,[1]Baseline!$D$3:$AZ$3,_xlfn.XLOOKUP(C101,[1]Baseline!$B$4:$B$91,[1]Baseline!$D$4:$AZ$91))} -> Awareness | E101: Governance | F101: =VLOOKUP($D101,'[1]SFIA Level'!$A$2:$B$6,2,FALSE) -> 1 | G101: 3 | H101: =I101-F101 -> 2 | I101: 3
... A177: Jane Marple | B177: Systems Analyst | C177: =VLOOKUP([1]Competence!$B99,[1]Competence!$B$12:$B$100,1,FALSE) -> Quality assurance | D177: {=_xlfn.XLOOKUP(B177,[1]Baseline!$D$3:$AZ$3,_xlfn.XLOOKUP(C177,[1]Baseline!$B$4:$B$91,[1]Baseline!$D$4:$AZ$91))} -> Awareness | E177: Technical | F177: =VLOOKUP($D177,'[1]SFIA Level'!$A$2:$B$6,2,FALSE) -> 1 | G177: 1 | H177: =I177-F177 -> 0 | I177: 1
A178: Endeavour Morse | B178: Systems Administrator | C178: =VLOOKUP([1]Competence!$B12,[1]Competence!$B$12:$B$100,1,FALSE) -> Asset Management | D178: {=_xlfn.XLOOKUP(B178,[1]Baseline!$D$3:$AZ$3,_xlfn.XLOOKUP(C178,[1]Baseline!$B$4:$B$91,[1]Baseline!$D$4:$AZ$91))} -> Working | E178: Service | F178: 3 | G178: 3 | H178: =I178-F178 -> 0 | I178: 3
A179: Endeavour Morse | B179: Systems Administrator | C179: =VLOOKUP([1]Competence!$B13,[1]Competence!$B$12:$B$100,1,FALSE) -> Change Control | D179: {=_xlfn.XLOOKUP(B179,[1]Baseline!$D$3:$AZ$3,_xlfn.XLOOKUP(C179,[1]Baseline!$B$4:$B$91,[1]Baseline!$D$4:$AZ$91))} -> Working | E179: Core | F179: 3 | G179: 1 | H179: =I179-F179 -> -2 | I179: 1
A180: Endeavour Morse | B180: Systems Administrator | C180: =VLOOKUP([1]Competence!$B14,[1]Competence!$B$12:$B$100,1,FALSE) -> Customer Service Support | D180: {=_xlfn.XLOOKUP(B180,[1]Baseline!$D$3:$AZ$3,_xlfn.XLOOKUP(C180,[1]Baseline!$B$4:$B$91,[1]Baseline!$D$4:$AZ$91))} -> Practitioner | E180: Service | F180: 2 | G180: 3 | H180: =I180-F180 -> 1 | I180: 3
A181: Endeavour Morse | B181: Systems Administrator | C181: =VLOOKUP([1]Competence!$B15,[1]Competence!$B$12:$B$100,1,FALSE) -> Incident management | D181: {=_xlfn.XLOOKUP(B181,[1]Baseline!$D$3:$AZ$3,_xlfn.XLOOKUP(C181,[1]Baseline!$B$4:$B$91,[1]Baseline!$D$4:$AZ$91))} -> Practitioner | E181: Service | F181: 2 | G181: 4 | H181: =I181-F181 -> 2 | I181: 4
A182: Endeavour Morse | B182: Systems Administrator | C182: =VLOOKUP([1]Competence!$B16,[1]Competence!$B$12:$B$100,1,FALSE) -> Information security | D182: {=_xlfn.XLOOKUP(B182,[1]Baseline!$D$3:$AZ$3,_xlfn.XLOOKUP(C182,[1]Baseline!$B$4:$B$91,[1]Baseline!$D$4:$AZ$91))} -> Working | E182: Service | F182: 2 | G182: 3 | H182: =I182-F182 -> 1 | I182: 3
A183: Endeavour Morse | B183: Systems Administrator | C183: =VLOOKUP([1]Competence!$B17,[1]Competence!$B$12:$B$100,1,FALSE) -> Personal data protection | D183: {=_xlfn.XLOOKUP(B183,[1]Baseline!$D$3:$AZ$3,_xlfn.XLOOKUP(C183,[1]Baseline!$B$4:$B$91,[1]Baseline!$D$4:$AZ$91))} -> Practitioner | E183: Security | F183: 2 | G183: 3 | H183: =I183-F183 -> 1 | I183: 3
A184: Endeavour Morse | B184: Systems Administrator | C184: =VLOOKUP([1]Competence!$B18,[1]Competence!$B$12:$B$100,1,FALSE) -> Problem management | D184: {=_xlfn.XLOOKUP(B184,[1]Baseline!$D$3:$AZ$3,_xlfn.XLOOKUP(C184,[1]Baseline!$B$4:$B$91,[1]Baseline!$D$4:$AZ$91))} -> Working | E184: Governance | F184: 2 | G184: 3 | H184: =I184-F184 -> 1 | I184: 3
A185: Endeavour Morse | B185: Systems Administrator | C185: =VLOOKUP([1]Competence!$B19,[1]Competence!$B$12:$B$100,1,FALSE) -> Service catalogue management | D185: {=_xlfn.XLOOKUP(B185,[1]Baseline!$D$3:$AZ$3,_xlfn.XLOOKUP(C185,[1]Baseline!$B$4:$B$91,[1]Baseline!$D$4:$AZ$91))} -> Working | E185: Governance | F185: 2 | G185: 3 | H185: =I185-F185 -> 1 | I185: 3
A186: Endeavour Morse | B186: Systems Administrator | C186: =VLOOKUP([1]Competence!$B20,[1]Competence!$B$12:$B$100,1,FALSE) -> Service level management | D186: {=_xlfn.XLOOKUP(B186,[1]Baseline!$D$3:$AZ$3,_xlfn.XLOOKUP(C186,[1]Baseline!$B$4:$B$91,[1]Baseline!$D$4:$AZ$91))} -> Working | E186: Technical | F186: 3 | G186: 3 | H186: =I186-F186 -> 0 | I186: 3
A187: Endeavour Morse | B187: Systems Administrator | C187: =VLOOKUP([1]Competence!$B21,[1]Competence!$B$12:$B$100,1,FALSE) -> Availability Management | D187: {=_xlfn.XLOOKUP(B187,[1]Baseline!$D$3:$AZ$3,_xlfn.XLOOKUP(C187,[1]Baseline!$B$4:$B$91,[1]Baseline!$D$4:$AZ$91))} -> Awareness | E187: Technical | F187: 2 | G187: 3 | H187: =I187-F187 -> 1 | I187: 3
A188: Endeavour Morse | B188: Systems Administrator | C188: =VLOOKUP([1]Competence!$B22,[1]Competence!$B$12:$B$100,1,FALSE) -> Capacity management | D188: {=_xlfn.XLOOKUP(B188,[1]Baseline!$D$3:$AZ$3,_xlfn.XLOOKUP(C188,[1]Baseline!$B$4:$B$91,[1]Baseline!$D$4:$AZ$91))} -> No Knowledge | E188: Technical | F188: 3 | G188: 0 | H188: =I188-F188 -> -3 | I188: 0
A189: Endeavour Morse | B189: Systems Administrator | C189: =VLOOKUP([1]Competence!$B23,[1]Competence!$B$12:$B$100,1,FALSE) -> Configuration Management | D189: {=_xlfn.XLOOKUP(B189,[1]Baseline!$D$3:$AZ$3,_xlfn.XLOOKUP(C189,[1]Baseline!$B$4:$B$91,[1]Baseline!$D$4:$AZ$91))} -> Awareness | E189: Technical | F189: 2 | G189: 1 | H189: =I189-F189 -> -1 | I189: 1
... A265: Endeavour Morse | B265: Systems Administrator | C265: =VLOOKUP([1]Competence!$B99,[1]Competence!$B$12:$B$100,1,FALSE) -> Quality assurance | D265: {=_xlfn.XLOOKUP(B265,[1]Baseline!$D$3:$AZ$3,_xlfn.XLOOKUP(C265,[1]Baseline!$B$4:$B$91,[1]Baseline!$D$4:$AZ$91))} -> Awareness | E265: Technical | F265: 0 | G265: 0 | H265: =I265-F265 -> 0 | I265: 0
...

Sheet Competence Heatmap
B1: Core | K1: Service | P1: Technical | BF1: Governance | BN1: Management | CE1: Security | CK1: Business
A2: Competence | B2: Asset Management | C2: Incident management | D2: Customer Service Support | E2: Problem management | F2: Personal data protection | G2: Service catalogue management | H2: Change Control | I2: Information security | J2: Service level management | K2: Availability Management | L2: Capacity management | M2: Configuration Management | N2: Continuity Management | O2: Demand Management | P2: Knowledge management | Q2: Methods and tools | R2: Release and deployment | S2: Service acceptance | T2: Stakeholder relationship management | U2: Storage management | V2: Acceptance testing | W2: Application support | X2: Data Engineering | Y2: Data Management | Z2: Data Modelling and Design | AA2: Data science | AB2: Data visualisation | AC2: Database Administration | AD2: Database Design | AE2: Hardware design | AF2: High Performance Computing | AG2: Research Computing | AH2: Information assurance | AI2: Information management | AJ2: Infrastructure | AK2: Network design | AL2: Network Analytics | AM2: Network support | AN2: Programming/software development | AO2: Real-time/embedded systems development | AP2: Requirements definition and management | AQ2: Software configuration | AR2: Software design | AS2: Solution architecture | AT2: System software | AU2: Systems and software life cycle engineering | AV2: Systems design | AW2: Systems development management | AX2: Systems installation and removal | AY2: Testing | AZ2: Innovation | BA2: Specialist Advice | BB2: Emerging technology monitoring | BC2: Systems integration and build | BD2: Audio Visual | BE2: Augmented Reality | BF2: Audit | BG2: Contract management | BH2: Feasibility assessment | BI2: Governance | BJ2: Risk management | BK2: Sourcing | BL2: Supplier management | BM2: Sustainability | BN2: Competency assessment | BO2: Financial management | BP2: Organisation design and implementation | BQ2: Organisational capability development | BR2: Organisational change management | BS2: Performance Management | BT2: Professional Development | BU2: Strategic Planning | BV2: Workforce Planning | BW2: Audit | BX2: Contract management | BY2: Feasibility assessment | BZ2: Governance | CA2: Risk management | CB2: Sourcing | CC2: Supplier management | CD2: Sustainability | CE2: Digital Forensics | CF2: Penetration testing | CG2: Security Operations | CH2: Threat Intelligence | CI2: Vulnerability assessment | CJ2: Vulnerability Research | CK2: Benefits management | CL2: Business administration | CM2: Business intelligence | CN2: Business modelling | CO2: Business process improvement | CP2: Business situation analysis | CQ2: Programme management | CR2: Project management | CS2: Quality assurance
A4: =VLOOKUP(Staff!$A1,Staff!$A$1:A$73,1,FALSE) -> Steve Arnott | B4: {=INDEX(Master!$I$2:'Master'!$I$4384,MATCH($A4&B$2,Master!$A$2:'Master'!$A$4384&Master!$C$2:'Master'!$C$4384,0))} -> 4 | C4: {=INDEX(Master!$I$2:'Master'!$I$4384,MATCH($A4&C$2,Master!$A$2:'Master'!$A$4384&Master!$C$2:'Master'!$C$4384,0))} -> 4 | D4: {=INDEX(Master!$I$2:'Master'!$I$4384,MATCH($A4&D$2,Master!$A$2:'Master'!$A$4384&Master!$C$2:'Master'!$C$4384,0))} -> 4 | E4: {=INDEX(Master!$I$2:'Master'!$I$4384,MATCH($A4&E$2,Master!$A$2:'Master'!$A$4384&Master!$C$2:'Master'!$C$4384,0))} -> 4 | F4: {=INDEX(Master!$I$2:'Master'!$I$4384,MATCH($A4&F$2,Master!$A$2:'Master'!$A$4384&Master!$C$2:'Master'!$C$4384,0))} -> 3 | G4: {=INDEX(Master!$I$2:'Master'!$I$4384,MATCH($A4&G$2,Master!$A$2:'Master'!$A$4384&Master!$C$2:'Master'!$C$4384,0))} -> 4 | H4: {=INDEX(Master!$I$2:'Master'!$I$4384,MATCH($A4&H$2,Master!$A$2:'Master'!$A$4384&Master!$C$2:'Master'!$C$4384,0))} -> 4 | I4: {=INDEX(Master!$I$2:'Master'!$I$4384,MATCH($A4&I$2,Master!$A$2:'Master'!$A$4384&Master!$C$2:'Master'!$C$4384,0))} -> 3 | ... CS4: {=INDEX(Master!$I$2:'Master'!$I$4384,MATCH($A4&CS$2,Master!$A$2:'Master'!$A$4384&Master!$C$2:'Master'!$C$4384,0))} -> 3
A5: =VLOOKUP(Staff!$A2,Staff!$A$1:A$73,1,FALSE) -> Humphrey Goodman | B5: {=INDEX(Master!$I$2:'Master'!$I$4384,MATCH($A5&B$2,Master!$A$2:'Master'!$A$4384&Master!$C$2:'Master'!$C$4384,0))} -> 3 | C5: {=INDEX(Master!$I$2:'Master'!$I$4384,MATCH($A5&C$2,Master!$A$2:'Master'!$A$4384&Master!$C$2:'Master'!$C$4384,0))} -> 4 | D5: {=INDEX(Master!$I$2:'Master'!$I$4384,MATCH($A5&D$2,Master!$A$2:'Master'!$A$4384&Master!$C$2:'Master'!$C$4384,0))} -> 4 | E5: {=INDEX(Master!$I$2:'Master'!$I$4384,MATCH($A5&E$2,Master!$A$2:'Master'!$A$4384&Master!$C$2:'Master'!$C$4384,0))} -> 4 | F5: {=INDEX(Master!$I$2:'Master'!$I$4384,MATCH($A5&F$2,Master!$A$2:'Master'!$A$4384&Master!$C$2:'Master'!$C$4384,0))} -> 4 | G5: {=INDEX(Master!$I$2:'Master'!$I$4384,MATCH($A5&G$2,Master!$A$2:'Master'!$A$4384&Master!$C$2:'Master'!$C$4384,0))} -> 4 | H5: {=INDEX(Master!$I$2:'Master'!$I$4384,MATCH($A5&H$2,Master!$A$2:'Master'!$A$4384&Master!$C$2:'Master'!$C$4384,0))} -> 3 | I5: {=INDEX(Master!$I$2:'Master'!$I$4384,MATCH($A5&I$2,Master!$A$2:'Master'!$A$4384&Master!$C$2:'Master'!$C$4384,0))} -> 3 | ... CS5: {=INDEX(Master!$I$2:'Master'!$I$4384,MATCH($A5&CS$2,Master!$A$2:'Master'!$A$4384&Master!$C$2:'Master'!$C$4384,0))} -> 2
